2023-04-22 19:32:43,146 INFO    StreamThr :64715 [internal.py:wandb_internal():86] W&B internal server running at pid: 64715, started at: 2023-04-22 19:32:43.146343
2023-04-22 19:32:43,148 DEBUG   HandlerThread:64715 [handler.py:handle_request():144] handle_request: status
2023-04-22 19:32:43,150 INFO    WriterThread:64715 [datastore.py:open_for_write():85] open: /Users/filip/thesis/wandb/run-20230422_193243-8ipywdvu/run-8ipywdvu.wandb
2023-04-22 19:32:43,152 DEBUG   SenderThread:64715 [sender.py:send():375] send: header
2023-04-22 19:32:43,182 DEBUG   SenderThread:64715 [sender.py:send():375] send: run
2023-04-22 19:32:46,676 INFO    SenderThread:64715 [retry.py:__call__():172] Retry attempt failed:
Traceback (most recent call last):
  File "/Users/filip/opt/anaconda3/lib/python3.9/site-packages/urllib3/connection.py", line 174, in _new_conn
    conn = connection.create_connection(
  File "/Users/filip/opt/anaconda3/lib/python3.9/site-packages/urllib3/util/connection.py", line 72, in create_connection
    for res in socket.getaddrinfo(host, port, family, socket.SOCK_STREAM):
  File "/Users/filip/opt/anaconda3/lib/python3.9/socket.py", line 954, in getaddrinfo
    for res in _socket.getaddrinfo(host, port, family, type, proto, flags):
socket.gaierror: [Errno 8] nodename nor servname provided, or not known

During handling of the above exception, another exception occurred:

Traceback (most recent call last):
  File "/Users/filip/opt/anaconda3/lib/python3.9/site-packages/urllib3/connectionpool.py", line 703, in urlopen
    httplib_response = self._make_request(
  File "/Users/filip/opt/anaconda3/lib/python3.9/site-packages/urllib3/connectionpool.py", line 386, in _make_request
    self._validate_conn(conn)
  File "/Users/filip/opt/anaconda3/lib/python3.9/site-packages/urllib3/connectionpool.py", line 1042, in _validate_conn
    conn.connect()
  File "/Users/filip/opt/anaconda3/lib/python3.9/site-packages/urllib3/connection.py", line 363, in connect
    self.sock = conn = self._new_conn()
  File "/Users/filip/opt/anaconda3/lib/python3.9/site-packages/urllib3/connection.py", line 186, in _new_conn
    raise NewConnectionError(
urllib3.exceptions.NewConnectionError: <urllib3.connection.HTTPSConnection object at 0x7fa6f58f6310>: Failed to establish a new connection: [Errno 8] nodename nor servname provided, or not known

During handling of the above exception, another exception occurred:

Traceback (most recent call last):
  File "/Users/filip/opt/anaconda3/lib/python3.9/site-packages/requests/adapters.py", line 439, in send
    resp = conn.urlopen(
  File "/Users/filip/opt/anaconda3/lib/python3.9/site-packages/urllib3/connectionpool.py", line 787, in urlopen
    retries = retries.increment(
  File "/Users/filip/opt/anaconda3/lib/python3.9/site-packages/urllib3/util/retry.py", line 592, in increment
    raise MaxRetryError(_pool, url, error or ResponseError(cause))
urllib3.exceptions.MaxRetryError: HTTPSConnectionPool(host='api.wandb.ai', port=443): Max retries exceeded with url: /graphql (Caused by NewConnectionError('<urllib3.connection.HTTPSConnection object at 0x7fa6f58f6310>: Failed to establish a new connection: [Errno 8] nodename nor servname provided, or not known'))

During handling of the above exception, another exception occurred:

Traceback (most recent call last):
  File "/Users/filip/opt/anaconda3/lib/python3.9/site-packages/wandb/sdk/lib/retry.py", line 131, in __call__
    result = self._call_fn(*args, **kwargs)
  File "/Users/filip/opt/anaconda3/lib/python3.9/site-packages/wandb/sdk/internal/internal_api.py", line 285, in execute
    return self.client.execute(*args, **kwargs)  # type: ignore
  File "/Users/filip/opt/anaconda3/lib/python3.9/site-packages/wandb/vendor/gql-0.2.0/wandb_gql/client.py", line 52, in execute
    result = self._get_result(document, *args, **kwargs)
  File "/Users/filip/opt/anaconda3/lib/python3.9/site-packages/wandb/vendor/gql-0.2.0/wandb_gql/client.py", line 60, in _get_result
    return self.transport.execute(document, *args, **kwargs)
  File "/Users/filip/opt/anaconda3/lib/python3.9/site-packages/wandb/sdk/lib/gql_request.py", line 55, in execute
    request = self.session.post(self.url, **post_args)
  File "/Users/filip/opt/anaconda3/lib/python3.9/site-packages/requests/sessions.py", line 590, in post
    return self.request('POST', url, data=data, json=json, **kwargs)
  File "/Users/filip/opt/anaconda3/lib/python3.9/site-packages/requests/sessions.py", line 542, in request
    resp = self.send(prep, **send_kwargs)
  File "/Users/filip/opt/anaconda3/lib/python3.9/site-packages/requests/sessions.py", line 655, in send
    r = adapter.send(request, **kwargs)
  File "/Users/filip/opt/anaconda3/lib/python3.9/site-packages/requests/adapters.py", line 516, in send
    raise ConnectionError(e, request=request)
requests.exceptions.ConnectionError: HTTPSConnectionPool(host='api.wandb.ai', port=443): Max retries exceeded with url: /graphql (Caused by NewConnectionError('<urllib3.connection.HTTPSConnection object at 0x7fa6f58f6310>: Failed to establish a new connection: [Errno 8] nodename nor servname provided, or not known'))
2023-04-22 19:32:48,197 DEBUG   HandlerThread:64715 [handler.py:handle_request():144] handle_request: keepalive
2023-04-22 19:32:53,205 DEBUG   HandlerThread:64715 [handler.py:handle_request():144] handle_request: keepalive
2023-04-22 19:32:58,253 DEBUG   HandlerThread:64715 [handler.py:handle_request():144] handle_request: keepalive
2023-04-22 19:33:03,257 DEBUG   HandlerThread:64715 [handler.py:handle_request():144] handle_request: keepalive
2023-04-22 19:33:08,264 DEBUG   HandlerThread:64715 [handler.py:handle_request():144] handle_request: keepalive
2023-04-22 19:33:13,282 DEBUG   HandlerThread:64715 [handler.py:handle_request():144] handle_request: keepalive
2023-04-22 19:33:18,305 DEBUG   HandlerThread:64715 [handler.py:handle_request():144] handle_request: keepalive
2023-04-22 19:33:23,324 DEBUG   HandlerThread:64715 [handler.py:handle_request():144] handle_request: keepalive
2023-04-22 19:33:28,338 DEBUG   HandlerThread:64715 [handler.py:handle_request():144] handle_request: keepalive
2023-04-22 19:33:33,355 DEBUG   HandlerThread:64715 [handler.py:handle_request():144] handle_request: keepalive
2023-04-22 19:33:38,362 DEBUG   HandlerThread:64715 [handler.py:handle_request():144] handle_request: keepalive
2023-04-22 19:33:43,381 DEBUG   HandlerThread:64715 [handler.py:handle_request():144] handle_request: cancel
2023-04-22 19:33:43,381 DEBUG   HandlerThread:64715 [handler.py:handle_request():144] handle_request: cancel
2023-04-22 19:33:43,382 DEBUG   SenderThread:64715 [sender.py:send():384] Record cancelled: run
2023-04-22 19:33:43,382 DEBUG   HandlerThread:64715 [handler.py:handle_request():144] handle_request: status_report
2023-04-22 19:33:43,400 DEBUG   HandlerThread:64715 [handler.py:handle_request():144] handle_request: shutdown
2023-04-22 19:33:43,400 INFO    HandlerThread:64715 [handler.py:finish():845] shutting down handler
2023-04-22 19:33:44,384 INFO    SenderThread:64715 [sender.py:finish():1550] shutting down sender
2023-04-22 19:33:44,385 INFO    WriterThread:64715 [datastore.py:close():298] close: /Users/filip/thesis/wandb/run-20230422_193243-8ipywdvu/run-8ipywdvu.wandb
